<?xml version='1.0' encoding='utf-8'?>
<mujoco model="thermal_cycler_biorad_c1000">
  <compiler angle="radian" autolimits="true" assetdir="../../assets" />
  <default>
    <default class="visual">
      <geom type="mesh" contype="0" conaffinity="0" density="0" group="2" />
      <mesh inertia="shell" />
    </default>
    <default class="inertia">
      <geom type="mesh" contype="0" conaffinity="0" group="5" />
      <mesh inertia="exact" />
    </default>
    <default class="collision">
      <geom type="mesh" contype="0" conaffinity="1" density="0" group="3" />
    </default>
  </default>
  <option gravity="0 0 0" />
  <asset>
    <mesh class="visual" name="body-visual-0" file="instrument/thermal_cycler_biorad_c1000/body-visual-0.obj" />
    <material name="body-0" rgba="0.498039 0.498039 0.498039 1" metallic="0.0" roughness="1.0" />
    <mesh class="visual" name="body-visual-1" file="instrument/thermal_cycler_biorad_c1000/body-visual-1.obj" />
    <material name="body-1" rgba="0.286275 0.662745 0.329412 1" metallic="0.0" roughness="1.0" />
    <mesh class="visual" name="body-visual-2" file="instrument/thermal_cycler_biorad_c1000/body-visual-2.obj" />
    <material name="body-2" rgba="0.84313725 0.81176471 0.70196078 1" metallic="0.0" roughness="1.0" />
    <mesh class="visual" name="body-visual-3" file="instrument/thermal_cycler_biorad_c1000/body-visual-3.obj" />
    <texture name="body-0" type="2d" file="instrument/thermal_cycler_biorad_c1000/body-0.png" />
    <material name="body-3" rgba="1 1 1 1" metallic="0.0" roughness="1.0" texture="body-0" />
    <mesh class="inertia" name="body-inertia" file="instrument/thermal_cycler_biorad_c1000/body-inertia.obj" />
    <mesh class="collision" name="body-collision-0" file="instrument/thermal_cycler_biorad_c1000/body-collision-0.obj" />
    <mesh class="visual" name="lid-visual-0" file="instrument/thermal_cycler_biorad_c1000/lid-visual-0.obj" />
    <material name="lid-0" rgba="0.84313725 0.81176471 0.70196078 1" metallic="0.0" roughness="1.0" />
    <mesh class="visual" name="lid-visual-1" file="instrument/thermal_cycler_biorad_c1000/lid-visual-1.obj" />
    <material name="lid-1" rgba="0.498039 0.498039 0.498039 1" metallic="0.0" roughness="1.0" />
    <mesh class="inertia" name="lid-inertia" file="instrument/thermal_cycler_biorad_c1000/lid-inertia.obj" />
    <mesh class="visual" name="lid-lever-visual-0" file="instrument/thermal_cycler_biorad_c1000/lid-lever-visual-0.obj" />
    <material name="lid-lever-0" rgba="0.286275 0.662745 0.329412 1" metallic="0.0" roughness="1.0" />
    <mesh class="visual" name="lid-lever-visual-1" file="instrument/thermal_cycler_biorad_c1000/lid-lever-visual-1.obj" />
    <material name="lid-lever-1" rgba="0.84313725 0.81176471 0.70196078 1" metallic="0.0" roughness="1.0" />
    <mesh class="inertia" name="lid-lever-inertia" file="instrument/thermal_cycler_biorad_c1000/lid-lever-inertia.obj" />
    <mesh class="visual" name="lid-force-knob-visual-0" file="instrument/thermal_cycler_biorad_c1000/lid-force-knob-visual-0.obj" />
    <material name="lid-force-knob-0" rgba="0.84313725 0.81176471 0.70196078 1" metallic="0.0" roughness="1.0" />
    <mesh class="inertia" name="lid-force-knob-inertia" file="instrument/thermal_cycler_biorad_c1000/lid-force-knob-inertia.obj" />
    <mesh class="visual" name="reaction-block-visual-0" file="instrument/thermal_cycler_biorad_c1000/reaction-block-visual-0.obj" />
    <material name="reaction-block-0" rgba="0.498039 0.498039 0.498039 1" metallic="0.0" roughness="1.0" />
    <mesh class="inertia" name="reaction-block-inertia" file="instrument/thermal_cycler_biorad_c1000/reaction-block-inertia.obj" />
  </asset>
  <extension>
    <plugin plugin="mjlab.passive.detent">
      <instance name="detent" />
    </plugin>
  </extension>
  <worldbody>
    <body name="body" pos="-0 -0.0621555 0.09735156" quat="0 0 0 1">
      <geom class="visual" mesh="body-visual-0" material="body-0" />
      <geom class="visual" mesh="body-visual-1" material="body-1" />
      <geom class="visual" mesh="body-visual-2" material="body-2" />
      <geom class="visual" mesh="body-visual-3" material="body-3" />
      <geom class="inertia" mesh="body-inertia" density="1000" />
      <geom class="collision" mesh="body-collision-0" />
      <geom class="collision" type="box" size="0.16531634 0.1768885 0.09141993" pos="0 -0.01750868 -0.00415259" />
      <geom class="collision" type="box" size="0.04705458 0.05891233 0.00550538" pos="-0.11857205 -0.0259347 0.09345097" />
      <geom class="collision" type="box" size="0.04705458 0.05891233 0.00550538" pos="0.11818152 -0.0259347 0.09345097" />
      <geom class="collision" type="box" size="0.16531634 0.05323186 0.00545543" pos="0 -0.13729936 0.09345097" />
      <geom class="collision" type="box" size="0.16531634 0.064804 0.00545543" pos="0 0.09293923 0.09345097" />
      <geom class="collision" type="box" size="0.11763413 0.03564314 0.01211631" pos="0 -0.11857569 0.10963205" />
      <geom class="collision" type="box" size="0.07844975 0.00706048 0.00431473" pos="0 0.04603181 0.1023905" />
      <body name="lid" pos="-0 -0.11407998 0.14201831" quat="0 -0 -0.15695801 0.98760528">
        <joint name="lid" type="hinge" pos="-0.07835153 0.00491715 -0.02499539" axis="-1 -0 0" range="-1.9 0" />
        <geom class="visual" mesh="lid-visual-0" material="lid-0" />
        <geom class="visual" mesh="lid-visual-1" material="lid-1" />
        <geom class="inertia" mesh="lid-inertia" density="1000" />
        <geom class="collision" type="box" size="0.056 0.01887199 0.01316" pos="-0.00085045 0.00096269 -0.01868714" quat="0.70710681 -0.70710675 0 0" />
        <geom class="collision" type="box" size="0.07751919 0.01744181 0.01968988" pos="-0.00023828 0.00745284 -0.00582981" quat="0.70710681 -0.70710675 0 0" />
        <geom class="collision" type="box" size="0.07751919 0.00635657 0.01968988" pos="-0.00023828 0.00745283 0.11228961" quat="0.70710681 -0.70710675 0 0" />
        <geom class="collision" type="box" size="0.07097511 0.00581996 0.02001498" pos="-0.07195542 0.00738207 0.04790889" quat="0.4999889 -0.49998886 0.5000111 0.50001114" />
        <geom class="collision" type="box" size="0.07097511 0.00581996 0.02001498" pos="0.07156257 0.00738207 0.04790889" quat="0.4999889 -0.49998886 0.5000111 0.50001114" />
        <geom class="collision" type="box" size="0.05709077 0.05115333 0.01804068" pos="-0.00213858 0.04121279 0.05533712" quat="0.70710681 -0.70710675 0 0" />
        <body name="lid-lever" pos="0.00000001 0.02497296 0.01787273" quat="0.99983132 0.01836635 0 -0">
          <joint name="lid-lever" type="hinge" pos="0.05808487 0.02498769 0.04570046" axis="-1 -0 -0" range="-0.94 0" springdamper="0.05 1" armature="0.0005" user="2" />
          <plugin instance="detent" />
          <geom class="visual" mesh="lid-lever-visual-0" material="lid-lever-0" />
          <geom class="visual" mesh="lid-lever-visual-1" material="lid-lever-1" />
          <geom class="inertia" mesh="lid-lever-inertia" density="1000" />
          <geom class="collision" type="box" size="0.07402492 0.00599602 0.0142868" pos="0.00000558 0.07184963 0.07713565" quat="0.95760974 0.28806872 -0 -0" />
          <geom class="collision" type="box" size="0.07402492 0.00599602 0.00673626" pos="0.00000558 0.10147841 0.10633726" quat="0.95760974 0.28806872 -0 -0" />
          <site name="lid-lever" pos="0.00000558 0.10147841 0.10633726" quat="0.95760974 0.28806872 -0 -0" rgba="1 0 0 1" />
          <geom class="collision" type="box" size="0.00745335 0.03336119 0.01475018" pos="-0.06579017 0.04027029 0.05656042" quat="0.95760974 0.28806872 -0 -0" />
          <geom class="collision" type="box" size="0.00745335 0.03336119 0.01475018" pos="0.06588534 0.04027029 0.05656042" quat="0.95760974 0.28806872 -0 -0" />
          <geom class="collision" type="box" size="0.00745335 0.03336119 0.00648441" pos="-0.06579017 0.07820781 0.09137272" quat="0.95760974 0.28806872 -0 -0" />
          <geom class="collision" type="box" size="0.00745335 0.03336119 0.00648441" pos="0.06595135 0.07820781 0.09137272" quat="0.95760974 0.28806872 -0 -0" />
        </body>
        <body name="lid-force-knob" pos="0.04853316 0.01582532 0.04458983" quat="0.76837396 0.00000003 -0.64000113 -0.00000001">
          <joint name="lid-force-knob" type="hinge" pos="0.00000062 0.04339292 0.04934651" axis="0 -1 0" range="0 60" frictionloss="0.01" damping="0.001"/>
          <site name="lid-force-knob" pos="0.00000062 0.04339292 0.04934651" quat="1 -1 0 0" />
          <geom class="visual" mesh="lid-force-knob-visual-0" material="lid-force-knob-0" />
          <geom class="inertia" mesh="lid-force-knob-inertia" density="1000" />
          <geom class="collision" type="sphere" size="0.02515104" pos="0.00008293 0.0370119 0.04934166" />
          <geom class="collision" type="cylinder" size="0.0239007 0.0032983" pos="0 0.04713839 0.04956995" quat="0.7071261 0.70708746 0 0" />
          <geom class="collision" type="box" size="0.02396715 0.01078522 0.00318763" pos="0 0.05702952 0.04948573" />
        </body>
      </body>
      <body name="reaction-block" pos="-0 -0.02582798 0.09007778" quat="1 -0 0 0">
        <geom class="visual" mesh="reaction-block-visual-0" material="reaction-block-0" />
        <geom class="inertia" mesh="reaction-block-inertia" density="1000" />
      </body>
    </body>
  </worldbody>
  <equality>
    <joint name="lid-lock" joint1="lid" polycoef="-1.9" active="false" />
  </equality>
  <actuator />
</mujoco>